04/Jan/2021 01:01:39 [Thread-1:123145379344384] [django.request:230] [ERROR]- Internal Server Error: /docs/
Traceback (most recent call last):
  File "/Users/kobetian/.virtualenvs/Renogyro/lib/python3.6/site-packages/django/core/handlers/exception.py", line 47, in inner
    response = get_response(request)
  File "/Users/kobetian/.virtualenvs/Renogyro/lib/python3.6/site-packages/django/core/handlers/base.py", line 179, in _get_response
    response = wrapped_callback(request, *callback_args, **callback_kwargs)
  File "/Users/kobetian/.virtualenvs/Renogyro/lib/python3.6/site-packages/django/views/decorators/csrf.py", line 54, in wrapped_view
    return view_func(*args, **kwargs)
  File "/Users/kobetian/.virtualenvs/Renogyro/lib/python3.6/site-packages/django/views/generic/base.py", line 70, in view
    return self.dispatch(request, *args, **kwargs)
  File "/Users/kobetian/.virtualenvs/Renogyro/lib/python3.6/site-packages/rest_framework/views.py", line 509, in dispatch
    response = self.handle_exception(exc)
  File "/Users/kobetian/.virtualenvs/Renogyro/lib/python3.6/site-packages/rest_framework/schemas/views.py", line 48, in handle_exception
    return super().handle_exception(exc)
  File "/Users/kobetian/.virtualenvs/Renogyro/lib/python3.6/site-packages/rest_framework/views.py", line 469, in handle_exception
    self.raise_uncaught_exception(exc)
  File "/Users/kobetian/.virtualenvs/Renogyro/lib/python3.6/site-packages/rest_framework/views.py", line 480, in raise_uncaught_exception
    raise exc
  File "/Users/kobetian/.virtualenvs/Renogyro/lib/python3.6/site-packages/rest_framework/views.py", line 506, in dispatch
    response = handler(request, *args, **kwargs)
  File "/Users/kobetian/.virtualenvs/Renogyro/lib/python3.6/site-packages/rest_framework/schemas/views.py", line 37, in get
    schema = self.schema_generator.get_schema(request, self.public)
  File "/Users/kobetian/.virtualenvs/Renogyro/lib/python3.6/site-packages/rest_framework/schemas/openapi.py", line 78, in get_schema
    if not self.has_view_permissions(path, method, view):
  File "/Users/kobetian/.virtualenvs/Renogyro/lib/python3.6/site-packages/rest_framework/schemas/generators.py", line 236, in has_view_permissions
    view.check_permissions(view.request)
  File "/Users/kobetian/.virtualenvs/Renogyro/lib/python3.6/site-packages/rest_framework/views.py", line 332, in check_permissions
    if not permission.has_permission(request, self):
  File "/Users/kobetian/.virtualenvs/Renogyro/lib/python3.6/site-packages/rest_framework/permissions.py", line 229, in has_permission
    queryset = self._queryset(view)
  File "/Users/kobetian/.virtualenvs/Renogyro/lib/python3.6/site-packages/rest_framework/permissions.py", line 209, in _queryset
    ).format(self.__class__.__name__)
AssertionError: Cannot apply DjangoModelPermissionsOrAnonReadOnly on a view that does not set `.queryset` or have a `.get_queryset()` method.
04/Jan/2021 01:01:44 [Thread-1:123145379344384] [django.request:230] [ERROR]- Internal Server Error: /docs/
Traceback (most recent call last):
  File "/Users/kobetian/.virtualenvs/Renogyro/lib/python3.6/site-packages/django/core/handlers/exception.py", line 47, in inner
    response = get_response(request)
  File "/Users/kobetian/.virtualenvs/Renogyro/lib/python3.6/site-packages/django/core/handlers/base.py", line 179, in _get_response
    response = wrapped_callback(request, *callback_args, **callback_kwargs)
  File "/Users/kobetian/.virtualenvs/Renogyro/lib/python3.6/site-packages/django/views/decorators/csrf.py", line 54, in wrapped_view
    return view_func(*args, **kwargs)
  File "/Users/kobetian/.virtualenvs/Renogyro/lib/python3.6/site-packages/django/views/generic/base.py", line 70, in view
    return self.dispatch(request, *args, **kwargs)
  File "/Users/kobetian/.virtualenvs/Renogyro/lib/python3.6/site-packages/rest_framework/views.py", line 509, in dispatch
    response = self.handle_exception(exc)
  File "/Users/kobetian/.virtualenvs/Renogyro/lib/python3.6/site-packages/rest_framework/schemas/views.py", line 48, in handle_exception
    return super().handle_exception(exc)
  File "/Users/kobetian/.virtualenvs/Renogyro/lib/python3.6/site-packages/rest_framework/views.py", line 469, in handle_exception
    self.raise_uncaught_exception(exc)
  File "/Users/kobetian/.virtualenvs/Renogyro/lib/python3.6/site-packages/rest_framework/views.py", line 480, in raise_uncaught_exception
    raise exc
  File "/Users/kobetian/.virtualenvs/Renogyro/lib/python3.6/site-packages/rest_framework/views.py", line 506, in dispatch
    response = handler(request, *args, **kwargs)
  File "/Users/kobetian/.virtualenvs/Renogyro/lib/python3.6/site-packages/rest_framework/schemas/views.py", line 37, in get
    schema = self.schema_generator.get_schema(request, self.public)
  File "/Users/kobetian/.virtualenvs/Renogyro/lib/python3.6/site-packages/rest_framework/schemas/openapi.py", line 78, in get_schema
    if not self.has_view_permissions(path, method, view):
  File "/Users/kobetian/.virtualenvs/Renogyro/lib/python3.6/site-packages/rest_framework/schemas/generators.py", line 236, in has_view_permissions
    view.check_permissions(view.request)
  File "/Users/kobetian/.virtualenvs/Renogyro/lib/python3.6/site-packages/rest_framework/views.py", line 332, in check_permissions
    if not permission.has_permission(request, self):
  File "/Users/kobetian/.virtualenvs/Renogyro/lib/python3.6/site-packages/rest_framework/permissions.py", line 229, in has_permission
    queryset = self._queryset(view)
  File "/Users/kobetian/.virtualenvs/Renogyro/lib/python3.6/site-packages/rest_framework/permissions.py", line 209, in _queryset
    ).format(self.__class__.__name__)
AssertionError: Cannot apply DjangoModelPermissionsOrAnonReadOnly on a view that does not set `.queryset` or have a `.get_queryset()` method.
04/Jan/2021 01:08:21 [Thread-1:123145472847872] [django.request:230] [ERROR]- Internal Server Error: /docs/
Traceback (most recent call last):
  File "/Users/kobetian/.virtualenvs/Renogyro/lib/python3.6/site-packages/django/core/handlers/exception.py", line 47, in inner
    response = get_response(request)
  File "/Users/kobetian/.virtualenvs/Renogyro/lib/python3.6/site-packages/django/core/handlers/base.py", line 179, in _get_response
    response = wrapped_callback(request, *callback_args, **callback_kwargs)
  File "/Users/kobetian/.virtualenvs/Renogyro/lib/python3.6/site-packages/django/views/decorators/csrf.py", line 54, in wrapped_view
    return view_func(*args, **kwargs)
  File "/Users/kobetian/.virtualenvs/Renogyro/lib/python3.6/site-packages/django/views/generic/base.py", line 70, in view
    return self.dispatch(request, *args, **kwargs)
  File "/Users/kobetian/.virtualenvs/Renogyro/lib/python3.6/site-packages/rest_framework/views.py", line 509, in dispatch
    response = self.handle_exception(exc)
  File "/Users/kobetian/.virtualenvs/Renogyro/lib/python3.6/site-packages/rest_framework/schemas/views.py", line 48, in handle_exception
    return super().handle_exception(exc)
  File "/Users/kobetian/.virtualenvs/Renogyro/lib/python3.6/site-packages/rest_framework/views.py", line 469, in handle_exception
    self.raise_uncaught_exception(exc)
  File "/Users/kobetian/.virtualenvs/Renogyro/lib/python3.6/site-packages/rest_framework/views.py", line 480, in raise_uncaught_exception
    raise exc
  File "/Users/kobetian/.virtualenvs/Renogyro/lib/python3.6/site-packages/rest_framework/views.py", line 506, in dispatch
    response = handler(request, *args, **kwargs)
  File "/Users/kobetian/.virtualenvs/Renogyro/lib/python3.6/site-packages/rest_framework/schemas/views.py", line 37, in get
    schema = self.schema_generator.get_schema(request, self.public)
  File "/Users/kobetian/.virtualenvs/Renogyro/lib/python3.6/site-packages/rest_framework/schemas/coreapi.py", line 156, in get_schema
    links = self.get_links(None if public else request)
  File "/Users/kobetian/.virtualenvs/Renogyro/lib/python3.6/site-packages/rest_framework/schemas/coreapi.py", line 143, in get_links
    link = view.schema.get_link(path, method, base_url=self.url)
AttributeError: 'AutoSchema' object has no attribute 'get_link'
04/Jan/2021 01:10:08 [Thread-1:123145324695552] [django.request:230] [ERROR]- Internal Server Error: /docs/
Traceback (most recent call last):
  File "/Users/kobetian/.virtualenvs/Renogyro/lib/python3.6/site-packages/django/core/handlers/exception.py", line 47, in inner
    response = get_response(request)
  File "/Users/kobetian/.virtualenvs/Renogyro/lib/python3.6/site-packages/django/core/handlers/base.py", line 179, in _get_response
    response = wrapped_callback(request, *callback_args, **callback_kwargs)
  File "/Users/kobetian/.virtualenvs/Renogyro/lib/python3.6/site-packages/django/views/decorators/csrf.py", line 54, in wrapped_view
    return view_func(*args, **kwargs)
  File "/Users/kobetian/.virtualenvs/Renogyro/lib/python3.6/site-packages/django/views/generic/base.py", line 70, in view
    return self.dispatch(request, *args, **kwargs)
  File "/Users/kobetian/.virtualenvs/Renogyro/lib/python3.6/site-packages/rest_framework/views.py", line 509, in dispatch
    response = self.handle_exception(exc)
  File "/Users/kobetian/.virtualenvs/Renogyro/lib/python3.6/site-packages/rest_framework/schemas/views.py", line 48, in handle_exception
    return super().handle_exception(exc)
  File "/Users/kobetian/.virtualenvs/Renogyro/lib/python3.6/site-packages/rest_framework/views.py", line 469, in handle_exception
    self.raise_uncaught_exception(exc)
  File "/Users/kobetian/.virtualenvs/Renogyro/lib/python3.6/site-packages/rest_framework/views.py", line 480, in raise_uncaught_exception
    raise exc
  File "/Users/kobetian/.virtualenvs/Renogyro/lib/python3.6/site-packages/rest_framework/views.py", line 506, in dispatch
    response = handler(request, *args, **kwargs)
  File "/Users/kobetian/.virtualenvs/Renogyro/lib/python3.6/site-packages/rest_framework/schemas/views.py", line 37, in get
    schema = self.schema_generator.get_schema(request, self.public)
  File "/Users/kobetian/.virtualenvs/Renogyro/lib/python3.6/site-packages/rest_framework/schemas/coreapi.py", line 154, in get_schema
    self._initialise_endpoints()
  File "/Users/kobetian/.virtualenvs/Renogyro/lib/python3.6/site-packages/rest_framework/schemas/generators.py", line 171, in _initialise_endpoints
    self.endpoints = inspector.get_api_endpoints()
  File "/Users/kobetian/.virtualenvs/Renogyro/lib/python3.6/site-packages/rest_framework/schemas/generators.py", line 94, in get_api_endpoints
    prefix=path_regex
  File "/Users/kobetian/.virtualenvs/Renogyro/lib/python3.6/site-packages/rest_framework/schemas/generators.py", line 86, in get_api_endpoints
    if self.should_include_endpoint(path, callback):
  File "/Users/kobetian/.virtualenvs/Renogyro/lib/python3.6/site-packages/rest_framework/schemas/generators.py", line 120, in should_include_endpoint
    if callback.cls.schema is None:
  File "/Users/kobetian/.virtualenvs/Renogyro/lib/python3.6/site-packages/rest_framework/schemas/inspectors.py", line 120, in __get__
    assert issubclass(inspector_class, ViewInspector), (
TypeError: issubclass() arg 1 must be a class
04/Jan/2021 01:14:27 [Thread-1:123145576189952] [django.request:230] [ERROR]- Internal Server Error: /docs/
Traceback (most recent call last):
  File "/Users/kobetian/.virtualenvs/Renogyro/lib/python3.6/site-packages/django/core/handlers/exception.py", line 47, in inner
    response = get_response(request)
  File "/Users/kobetian/.virtualenvs/Renogyro/lib/python3.6/site-packages/django/core/handlers/base.py", line 179, in _get_response
    response = wrapped_callback(request, *callback_args, **callback_kwargs)
  File "/Users/kobetian/.virtualenvs/Renogyro/lib/python3.6/site-packages/django/views/decorators/csrf.py", line 54, in wrapped_view
    return view_func(*args, **kwargs)
  File "/Users/kobetian/.virtualenvs/Renogyro/lib/python3.6/site-packages/django/views/generic/base.py", line 70, in view
    return self.dispatch(request, *args, **kwargs)
  File "/Users/kobetian/.virtualenvs/Renogyro/lib/python3.6/site-packages/rest_framework/views.py", line 509, in dispatch
    response = self.handle_exception(exc)
  File "/Users/kobetian/.virtualenvs/Renogyro/lib/python3.6/site-packages/rest_framework/views.py", line 469, in handle_exception
    self.raise_uncaught_exception(exc)
  File "/Users/kobetian/.virtualenvs/Renogyro/lib/python3.6/site-packages/rest_framework/views.py", line 480, in raise_uncaught_exception
    raise exc
  File "/Users/kobetian/.virtualenvs/Renogyro/lib/python3.6/site-packages/rest_framework/views.py", line 506, in dispatch
    response = handler(request, *args, **kwargs)
  File "/Users/kobetian/.virtualenvs/Renogyro/lib/python3.6/site-packages/rest_framework_swagger/views.py", line 32, in get
    schema = generator.get_schema(request=request)
  File "/Users/kobetian/.virtualenvs/Renogyro/lib/python3.6/site-packages/rest_framework/schemas/coreapi.py", line 156, in get_schema
    links = self.get_links(None if public else request)
  File "/Users/kobetian/.virtualenvs/Renogyro/lib/python3.6/site-packages/rest_framework/schemas/coreapi.py", line 141, in get_links
    if not self.has_view_permissions(path, method, view):
  File "/Users/kobetian/.virtualenvs/Renogyro/lib/python3.6/site-packages/rest_framework/schemas/generators.py", line 236, in has_view_permissions
    view.check_permissions(view.request)
  File "/Users/kobetian/.virtualenvs/Renogyro/lib/python3.6/site-packages/rest_framework/views.py", line 332, in check_permissions
    if not permission.has_permission(request, self):
  File "/Users/kobetian/.virtualenvs/Renogyro/lib/python3.6/site-packages/rest_framework/permissions.py", line 229, in has_permission
    queryset = self._queryset(view)
  File "/Users/kobetian/.virtualenvs/Renogyro/lib/python3.6/site-packages/rest_framework/permissions.py", line 209, in _queryset
    ).format(self.__class__.__name__)
AssertionError: Cannot apply DjangoModelPermissionsOrAnonReadOnly on a view that does not set `.queryset` or have a `.get_queryset()` method.
04/Jan/2021 01:15:01 [Thread-1:123145386070016] [django.request:230] [ERROR]- Internal Server Error: /docs/
Traceback (most recent call last):
  File "/Users/kobetian/.virtualenvs/Renogyro/lib/python3.6/site-packages/django/template/defaulttags.py", line 1034, in find_library
    return parser.libraries[name]
KeyError: 'staticfiles'

During handling of the above exception, another exception occurred:

Traceback (most recent call last):
  File "/Users/kobetian/.virtualenvs/Renogyro/lib/python3.6/site-packages/django/core/handlers/exception.py", line 47, in inner
    response = get_response(request)
  File "/Users/kobetian/.virtualenvs/Renogyro/lib/python3.6/site-packages/django/core/handlers/base.py", line 202, in _get_response
    response = response.render()
  File "/Users/kobetian/.virtualenvs/Renogyro/lib/python3.6/site-packages/django/template/response.py", line 105, in render
    self.content = self.rendered_content
  File "/Users/kobetian/.virtualenvs/Renogyro/lib/python3.6/site-packages/rest_framework/response.py", line 70, in rendered_content
    ret = renderer.render(self.data, accepted_media_type, context)
  File "/Users/kobetian/.virtualenvs/Renogyro/lib/python3.6/site-packages/rest_framework_swagger/renderers.py", line 58, in render
    renderer_context
  File "/Users/kobetian/.virtualenvs/Renogyro/lib/python3.6/site-packages/django/shortcuts.py", line 19, in render
    content = loader.render_to_string(template_name, context, request, using=using)
  File "/Users/kobetian/.virtualenvs/Renogyro/lib/python3.6/site-packages/django/template/loader.py", line 61, in render_to_string
    template = get_template(template_name, using=using)
  File "/Users/kobetian/.virtualenvs/Renogyro/lib/python3.6/site-packages/django/template/loader.py", line 15, in get_template
    return engine.get_template(template_name)
  File "/Users/kobetian/.virtualenvs/Renogyro/lib/python3.6/site-packages/django/template/backends/django.py", line 34, in get_template
    return Template(self.engine.get_template(template_name), self)
  File "/Users/kobetian/.virtualenvs/Renogyro/lib/python3.6/site-packages/django/template/engine.py", line 143, in get_template
    template, origin = self.find_template(template_name)
  File "/Users/kobetian/.virtualenvs/Renogyro/lib/python3.6/site-packages/django/template/engine.py", line 125, in find_template
    template = loader.get_template(name, skip=skip)
  File "/Users/kobetian/.virtualenvs/Renogyro/lib/python3.6/site-packages/django/template/loaders/base.py", line 30, in get_template
    contents, origin, origin.template_name, self.engine,
  File "/Users/kobetian/.virtualenvs/Renogyro/lib/python3.6/site-packages/django/template/base.py", line 155, in __init__
    self.nodelist = self.compile_nodelist()
  File "/Users/kobetian/.virtualenvs/Renogyro/lib/python3.6/site-packages/django/template/base.py", line 193, in compile_nodelist
    return parser.parse()
  File "/Users/kobetian/.virtualenvs/Renogyro/lib/python3.6/site-packages/django/template/base.py", line 478, in parse
    raise self.error(token, e)
  File "/Users/kobetian/.virtualenvs/Renogyro/lib/python3.6/site-packages/django/template/base.py", line 476, in parse
    compiled_result = compile_func(self, token)
  File "/Users/kobetian/.virtualenvs/Renogyro/lib/python3.6/site-packages/django/template/defaulttags.py", line 1091, in load
    lib = find_library(parser, name)
  File "/Users/kobetian/.virtualenvs/Renogyro/lib/python3.6/site-packages/django/template/defaulttags.py", line 1038, in find_library
    name, "\n".join(sorted(parser.libraries)),
django.template.exceptions.TemplateSyntaxError: 'staticfiles' is not a registered tag library. Must be one of:
admin_list
admin_modify
admin_urls
cache
i18n
l10n
log
rest_framework
static
tz
04/Jan/2021 01:15:35 [Thread-1:123145571106816] [django.request:230] [ERROR]- Internal Server Error: /docs/
Traceback (most recent call last):
  File "/Users/kobetian/.virtualenvs/Renogyro/lib/python3.6/site-packages/django/template/defaulttags.py", line 1034, in find_library
    return parser.libraries[name]
KeyError: 'staticfiles'

During handling of the above exception, another exception occurred:

Traceback (most recent call last):
  File "/Users/kobetian/.virtualenvs/Renogyro/lib/python3.6/site-packages/django/core/handlers/exception.py", line 47, in inner
    response = get_response(request)
  File "/Users/kobetian/.virtualenvs/Renogyro/lib/python3.6/site-packages/django/core/handlers/base.py", line 202, in _get_response
    response = response.render()
  File "/Users/kobetian/.virtualenvs/Renogyro/lib/python3.6/site-packages/django/template/response.py", line 105, in render
    self.content = self.rendered_content
  File "/Users/kobetian/.virtualenvs/Renogyro/lib/python3.6/site-packages/rest_framework/response.py", line 70, in rendered_content
    ret = renderer.render(self.data, accepted_media_type, context)
  File "/Users/kobetian/.virtualenvs/Renogyro/lib/python3.6/site-packages/rest_framework_swagger/renderers.py", line 58, in render
    renderer_context
  File "/Users/kobetian/.virtualenvs/Renogyro/lib/python3.6/site-packages/django/shortcuts.py", line 19, in render
    content = loader.render_to_string(template_name, context, request, using=using)
  File "/Users/kobetian/.virtualenvs/Renogyro/lib/python3.6/site-packages/django/template/loader.py", line 61, in render_to_string
    template = get_template(template_name, using=using)
  File "/Users/kobetian/.virtualenvs/Renogyro/lib/python3.6/site-packages/django/template/loader.py", line 15, in get_template
    return engine.get_template(template_name)
  File "/Users/kobetian/.virtualenvs/Renogyro/lib/python3.6/site-packages/django/template/backends/django.py", line 34, in get_template
    return Template(self.engine.get_template(template_name), self)
  File "/Users/kobetian/.virtualenvs/Renogyro/lib/python3.6/site-packages/django/template/engine.py", line 143, in get_template
    template, origin = self.find_template(template_name)
  File "/Users/kobetian/.virtualenvs/Renogyro/lib/python3.6/site-packages/django/template/engine.py", line 125, in find_template
    template = loader.get_template(name, skip=skip)
  File "/Users/kobetian/.virtualenvs/Renogyro/lib/python3.6/site-packages/django/template/loaders/base.py", line 30, in get_template
    contents, origin, origin.template_name, self.engine,
  File "/Users/kobetian/.virtualenvs/Renogyro/lib/python3.6/site-packages/django/template/base.py", line 155, in __init__
    self.nodelist = self.compile_nodelist()
  File "/Users/kobetian/.virtualenvs/Renogyro/lib/python3.6/site-packages/django/template/base.py", line 193, in compile_nodelist
    return parser.parse()
  File "/Users/kobetian/.virtualenvs/Renogyro/lib/python3.6/site-packages/django/template/base.py", line 478, in parse
    raise self.error(token, e)
  File "/Users/kobetian/.virtualenvs/Renogyro/lib/python3.6/site-packages/django/template/base.py", line 476, in parse
    compiled_result = compile_func(self, token)
  File "/Users/kobetian/.virtualenvs/Renogyro/lib/python3.6/site-packages/django/template/defaulttags.py", line 1091, in load
    lib = find_library(parser, name)
  File "/Users/kobetian/.virtualenvs/Renogyro/lib/python3.6/site-packages/django/template/defaulttags.py", line 1038, in find_library
    name, "\n".join(sorted(parser.libraries)),
django.template.exceptions.TemplateSyntaxError: 'staticfiles' is not a registered tag library. Must be one of:
admin_list
admin_modify
admin_urls
cache
i18n
l10n
log
rest_framework
static
tz
04/Jan/2021 01:15:37 [Thread-1:123145571106816] [django.request:230] [ERROR]- Internal Server Error: /docs/
Traceback (most recent call last):
  File "/Users/kobetian/.virtualenvs/Renogyro/lib/python3.6/site-packages/django/template/defaulttags.py", line 1034, in find_library
    return parser.libraries[name]
KeyError: 'staticfiles'

During handling of the above exception, another exception occurred:

Traceback (most recent call last):
  File "/Users/kobetian/.virtualenvs/Renogyro/lib/python3.6/site-packages/django/core/handlers/exception.py", line 47, in inner
    response = get_response(request)
  File "/Users/kobetian/.virtualenvs/Renogyro/lib/python3.6/site-packages/django/core/handlers/base.py", line 202, in _get_response
    response = response.render()
  File "/Users/kobetian/.virtualenvs/Renogyro/lib/python3.6/site-packages/django/template/response.py", line 105, in render
    self.content = self.rendered_content
  File "/Users/kobetian/.virtualenvs/Renogyro/lib/python3.6/site-packages/rest_framework/response.py", line 70, in rendered_content
    ret = renderer.render(self.data, accepted_media_type, context)
  File "/Users/kobetian/.virtualenvs/Renogyro/lib/python3.6/site-packages/rest_framework_swagger/renderers.py", line 58, in render
    renderer_context
  File "/Users/kobetian/.virtualenvs/Renogyro/lib/python3.6/site-packages/django/shortcuts.py", line 19, in render
    content = loader.render_to_string(template_name, context, request, using=using)
  File "/Users/kobetian/.virtualenvs/Renogyro/lib/python3.6/site-packages/django/template/loader.py", line 61, in render_to_string
    template = get_template(template_name, using=using)
  File "/Users/kobetian/.virtualenvs/Renogyro/lib/python3.6/site-packages/django/template/loader.py", line 15, in get_template
    return engine.get_template(template_name)
  File "/Users/kobetian/.virtualenvs/Renogyro/lib/python3.6/site-packages/django/template/backends/django.py", line 34, in get_template
    return Template(self.engine.get_template(template_name), self)
  File "/Users/kobetian/.virtualenvs/Renogyro/lib/python3.6/site-packages/django/template/engine.py", line 143, in get_template
    template, origin = self.find_template(template_name)
  File "/Users/kobetian/.virtualenvs/Renogyro/lib/python3.6/site-packages/django/template/engine.py", line 125, in find_template
    template = loader.get_template(name, skip=skip)
  File "/Users/kobetian/.virtualenvs/Renogyro/lib/python3.6/site-packages/django/template/loaders/base.py", line 30, in get_template
    contents, origin, origin.template_name, self.engine,
  File "/Users/kobetian/.virtualenvs/Renogyro/lib/python3.6/site-packages/django/template/base.py", line 155, in __init__
    self.nodelist = self.compile_nodelist()
  File "/Users/kobetian/.virtualenvs/Renogyro/lib/python3.6/site-packages/django/template/base.py", line 193, in compile_nodelist
    return parser.parse()
  File "/Users/kobetian/.virtualenvs/Renogyro/lib/python3.6/site-packages/django/template/base.py", line 478, in parse
    raise self.error(token, e)
  File "/Users/kobetian/.virtualenvs/Renogyro/lib/python3.6/site-packages/django/template/base.py", line 476, in parse
    compiled_result = compile_func(self, token)
  File "/Users/kobetian/.virtualenvs/Renogyro/lib/python3.6/site-packages/django/template/defaulttags.py", line 1091, in load
    lib = find_library(parser, name)
  File "/Users/kobetian/.virtualenvs/Renogyro/lib/python3.6/site-packages/django/template/defaulttags.py", line 1038, in find_library
    name, "\n".join(sorted(parser.libraries)),
django.template.exceptions.TemplateSyntaxError: 'staticfiles' is not a registered tag library. Must be one of:
admin_list
admin_modify
admin_urls
cache
i18n
l10n
log
rest_framework
static
tz
